<?xml version="1.0"?>
<robot name="mybot">
  <material name="black">
    <color rgba="0 0 0 1"/>
  </material>
  <material name="grey">
    <color rgba="0.5 0.5 0.5 1"/>
  </material>
  <material name="red">
    <color rgba="1 0 0 1"/>
  </material>

  <link name="camera">
    <visual>
      <geometry>
        <box size="0.05 0.05 0.05"/>
        <origin rpy="0 0 0" xyz="0 0 0"/>
      </geometry>
      <material name="red" />
    </visual>
    <collision>
      <geometry>
        <box size="0.1 0.1 0.1"/>
        <origin rpy="0 0 0" xyz="0 0 0"/>
      </geometry>    
    </collision>
    <inertial>
      <mass value="0.1"/>
      <inertia ixx="0.1" ixy="0" ixz="0" iyy="0.1" iyz="0" izz="0.1"/>
    </inertial>
  </link>

  <joint name="joint_camera_base_link" type="fixed">
    <origin rpy="0 0 0" xyz="0 -0.25 0"/>
    <parent link="base_link"/>
    <child link="camera"/>
  </joint>

  <link name="base_link">
    <visual>
      <geometry>
        <box size="0.5 0.5 0.1"/>
        <origin rpy="0 0 0" xyz="0 0 0"/>
      </geometry>
      <material name="black" />
    </visual>
    <collision>
      <geometry>
        <box size="0.5 0.5 0.1"/>
        <origin rpy="0 0 0" xyz="0 0 0"/>
      </geometry>
    </collision>
    <inertial>
      <mass value="1"/>
      <inertia ixx="0.1" ixy="0" ixz="0" iyy="0.1" iyz="0" izz="0.1"/>
    </inertial>
  </link>

  <link name="link1_1">
    <visual>
      <geometry>
        <cylinder length="0.1" radius="0.075"/>
        <origin rpy="0 0 0" xyz="0 0 0"/>
      </geometry>
      <material name="grey" />
    </visual>
    <collision>
      <geometry>
        <cylinder length="0.1" radius="0.075"/>
        <origin rpy="0 0 0" xyz="0 0 0"/>
      </geometry>
    </collision>
    <inertial>
      <mass value="1"/>
      <inertia ixx="0.1" ixy="0" ixz="0" iyy="0.1" iyz="0" izz="0.1"/>
    </inertial>
  </link>

  <joint name="joint_base_link1_1" type="revolute">
    <origin rpy="0 0 0" xyz="0.075 0 -0.1"/>
    <parent link="base_link"/>
    <child link="link1_1"/>
    <axis xyz="0 0 1"/>
    <limit effort="100" velocity="1" lower="-0.26017" upper="0.26017"/>
  </joint>

  <link name="link1_2">
    <visual>
        <geometry>
            <cylinder length="0.1" radius="0.075"/>
            <origin rpy="0 0 0" xyz="0 0 0"/>
        </geometry>
        <material name="grey" />
    </visual>
    <collision>
        <geometry>
            <cylinder length="0.1" radius="0.075"/>
            <origin rpy="0 0 0" xyz="0 0 0"/>
        </geometry>
    </collision>
    <inertial>
        <mass value="1"/>
        <inertia ixx="0.1" ixy="0" ixz="0" iyy="0.1" iyz="0" izz="0.1"/>
    </inertial>
  </link>

  <joint name="joint_base_link1_2" type="revolute">
    <origin rpy="0 0 0" xyz="-0.075 0 -0.1"/>
    <parent link="base_link"/>
    <child link="link1_2"/>
    <axis xyz="0 0 1"/>
    <limit effort="100" velocity="1" lower="-0.26017" upper="0.26017"/>
  </joint>

  <link name="link2_1">
    <visual>
      <geometry>
        <box size="0.25 0.1 0.05"/>
        <origin rpy="0 0 0" xyz="0 0 0"/>
      </geometry>
      <material name="black" />
    </visual>
    <collision>
      <geometry>
        <box size="0.25 0.1 0.05"/>
        <origin rpy="0 0 0" xyz="0 0 0"/>
      </geometry>
    </collision>
    <inertial>
      <mass value="1"/>
      <inertia ixx="0.1" ixy="0" ixz="0" iyy="0.1" iyz="0" izz="0.1"/>
    </inertial>
  </link>

  <joint name="joint_link1_1_link2_1" type="fixed">
    <origin rpy="0 0 0" xyz="0.075 0 -0.075"/>
    <parent link="link1_1"/>
    <child link="link2_1"/>
  </joint>

  <link name="link2_2">
    <visual>
      <geometry>
        <box size="0.25 0.1 0.05"/>
        <origin rpy="0 0 0" xyz="0 0 0"/>
      </geometry>
      <material name="black" />
    </visual>
    <collision>
      <geometry>
        <box size="0.25 0.1 0.05"/>
        <origin rpy="0 0 0" xyz="0 0 0"/>
      </geometry>
    </collision>
    <inertial>
      <mass value="1"/>
      <inertia ixx="0.1" ixy="0" ixz="0" iyy="0.1" iyz="0" izz="0.1"/>
    </inertial>
  </link>

  <joint name="joint_link1_2_link2_2" type="fixed">
    <origin rpy="0 0 0" xyz="-0.075 0 -0.075"/>
    <parent link="link1_2"/>
    <child link="link2_2"/>
  </joint>

  <link name="link3">
    <visual>
      <geometry>
        <cylinder length="0.1" radius="0.075"/>
        <origin rpy="0 0 0" xyz="0 0 0"/>
      </geometry>
      <material name="grey" />
    </visual>
    <collision>
      <geometry>
        <cylinder length="0.1" radius="0.075"/>
        <origin rpy="0 0 0" xyz="0 0 0"/>
      </geometry>
    </collision>
    <inertial>
      <mass value="1"/>
      <inertia ixx="0.1" ixy="0" ixz="0" iyy="0.1" iyz="0" izz="0.1"/>
    </inertial>
  </link>

  <joint name="joint_link2_link3" type="revolute">
    <origin rpy="1.57 1.57 0" xyz="0.07 0 0"/>
    <parent link="link2_1"/>
    <child link="link3"/>
    <axis xyz="0 0 1"/>
    <limit effort="100" velocity="1" lower="-0.13" upper="0.13"/>
  </joint>

  <link name="link4">
    <visual>
      <geometry>
        <cylinder length="0.1" radius="0.075"/>
        <origin rpy="0 0 0" xyz="0 0 0"/>
      </geometry>
      <material name="grey" />
    </visual>
    <collision>
      <geometry>
        <cylinder length="0.1" radius="0.075"/>
        <origin rpy="0 0 0" xyz="0 0 0"/>
      </geometry>
    </collision>
    <inertial>
      <mass value="1"/>
      <inertia ixx="0.1" ixy="0" ixz="0" iyy="0.1" iyz="0" izz="0.1"/>
    </inertial>
  </link>

  <joint name="joint_link2_link4" type="revolute">
    <origin rpy="1.57 1.57 0" xyz="-0.07 0 0.0"/>
    <parent link="link2_2"/>
    <child link="link4"/>
    <axis xyz="0 0 1"/>
    <limit effort="100" velocity="1" lower="-0.13" upper="0.13"/>
  </joint>

  <link name="link5">
    <visual>
      <geometry>
        <cylinder length="0.075" radius="0.08"/>
        <origin rpy="0 0 0" xyz="0 0 0"/>
      </geometry>
      <material name="grey" />
    </visual>
    <collision>
      <geometry>
        <cylinder length="0.075" radius="0.08"/>
        <origin rpy="0 0 0" xyz="0 0 0"/>
      </geometry>
    </collision>
    <inertial>
      <mass value="1"/>
      <inertia ixx="0.1" ixy="0" ixz="0" iyy="0.1" iyz="0" izz="0.1"/>
    </inertial>
  </link>

  <joint name="joint_link3_link5" type="revolute">
    <origin rpy="1.57 0.2 0" xyz="0 0.1 0.025"/>
    <parent link="link3"/>
    <child link="link5"/>
    <axis xyz="0 0 1"/>
    <limit effort="100" velocity="1" lower="-0.165" upper="0.365"/>
  </joint>

  <link name="link6">
    <visual>
      <geometry>
        <cylinder length="0.075" radius="0.08"/>
        <origin rpy="0 0 0" xyz="0 0 0"/>
      </geometry>
      <material name="grey" />
    </visual>
    <collision>
      <geometry>
        <cylinder length="0.075" radius="0.08"/>
        <origin rpy="0 0 0" xyz="0 0 0"/>
      </geometry>
    </collision>
    <inertial>
      <mass value="1"/>
      <inertia ixx="0.1" ixy="0" ixz="0" iyy="0.1" iyz="0" izz="0.1"/>
    </inertial>
  </link>

  <joint name="joint_link4_link6" type="revolute">
    <origin rpy="1.57 0.2 0" xyz="0 -0.1 0.025"/>
    <parent link="link4"/>
    <child link="link6"/>
    <axis xyz="0 0 1"/>
    <limit effort="100" velocity="1" lower="-0.165" upper="0.365"/>
  </joint>

  <link name="link7">
    <visual>
      <geometry>
        <box size="0.25 0.1 0.07"/>
        <origin rpy="0 0 0" xyz="0 0 0"/>
      </geometry>
      <material name="black" />
    </visual>
    <collision>
      <geometry>
        <box size="0.25 0.1 0.07"/>
        <origin rpy="0 0 0" xyz="0 0 0"/>
      </geometry>
    </collision>
    <inertial>
      <mass value="1"/>
      <inertia ixx="0.1" ixy="0" ixz="0" iyy="0.1" iyz="0" izz="0.1"/>
    </inertial>
  </link>

  <joint name="joint_link5_link7" type="fixed">
    <origin rpy="0 0 -0.885" xyz="0.09 -0.09 0"/>
    <parent link="link5"/>
    <child link="link7"/>
    <axis xyz="0 0 1"/>
    <limit effort="100" velocity="1" lower="-0.065" upper="0.565"/>
  </joint>

  <link name="link8">
    <visual>
      <geometry>
        <box size="0.25 0.1 0.07"/>
        <origin rpy="0 0 0" xyz="0 0 0"/>
      </geometry>
      <material name="black" />
    </visual>
    <collision>
      <geometry>
        <box size="0.25 0.1 0.07"/>
        <origin rpy="0 0 0" xyz="0 0 0"/>
      </geometry>
    </collision>
    <inertial>
      <mass value="1"/>
      <inertia ixx="0.1" ixy="0" ixz="0" iyy="0.1" iyz="0" izz="0.1"/>
    </inertial>
  </link>

  <joint name="joint_link6_link8" type="fixed">
    <origin rpy="0 0 -0.885" xyz="0.09 -0.09 0"/>
    <parent link="link6"/>
    <child link="link8"/>
    <axis xyz="0 0 1"/>
    <limit effort="100" velocity="1" lower="-0.065" upper="0.565"/>
  </joint>

  <link name="link9">
    <visual>
      <geometry>
        <cylinder length="0.075" radius="0.065"/>
        <origin rpy="0 0 0" xyz="0 0 0"/>
      </geometry>
      <material name="grey" />
    </visual>
    <collision>
      <geometry>
        <cylinder length="0.075" radius="0.065"/>
        <origin rpy="0 0 0" xyz="0 0 0"/>
      </geometry>
    </collision>
    <inertial>
      <mass value="1"/>
      <inertia ixx="0.1" ixy="0" ixz="0" iyy="0.1" iyz="0" izz="0.1"/>
    </inertial>
  </link>

  <joint name="joint_link7_link9" type="revolute">
    <origin rpy="0 0 -0.885" xyz="0.125 0.015 0"/>
    <parent link="link7"/>
    <child link="link9"/>
    <axis xyz="0 0 1"/>
    <limit effort="100" velocity="1" lower="-0.065" upper="0.565"/>
  </joint>

  <link name="link10">
    <visual>
      <geometry>
        <cylinder length="0.075" radius="0.065"/>
        <origin rpy="0 0 0" xyz="0 0 0"/>
      </geometry>
      <material name="grey" />
    </visual>
    <collision>
      <geometry>
        <cylinder length="0.075" radius="0.065"/>
        <origin rpy="0 0 0" xyz="0 0 0"/>
      </geometry>
    </collision>
    <inertial>
      <mass value="1"/>
      <inertia ixx="0.1" ixy="0" ixz="0" iyy="0.1" iyz="0" izz="0.1"/>
    </inertial>
  </link>

  <joint name="joint_link8_link10" type="revolute">
    <origin rpy="0 0 -0.885" xyz="0.125 0.015 0"/>
    <parent link="link8"/>
    <child link="link10"/>
    <axis xyz="0 0 1"/>
    <limit effort="100" velocity="1" lower="-0.065" upper="0.565"/>
  </joint>

  <link name="link11">
    <visual>
      <geometry>
        <box size="0.2 0.1 0.05"/>
        <origin rpy="0 0 0" xyz="0 0 0"/>
      </geometry>
      <material name="black" />
    </visual>
    <collision>
      <geometry>
        <box size="0.2 0.1 0.05"/>
        <origin rpy="0 0 0" xyz="0 0 0"/>
      </geometry>
    </collision>
    <inertial>
      <mass value="1"/>
      <inertia ixx="0.1" ixy="0" ixz="0" iyy="0.1" iyz="0" izz="0.1"/>
    </inertial>
  </link>

  <joint name="joint_link9_link11" type="fixed">
    <origin rpy="0 0 -0.75" xyz="-0.05 0.06 0"/>
    <parent link="link9"/>
    <child link="link11"/>
    <axis xyz="0 0 1"/>
    <limit effort="100" velocity="1" lower="-0.065" upper="0.565"/>
  </joint>

  <link name="link12">
    <visual>
      <geometry>
        <box size="0.2 0.1 0.05"/>
        <origin rpy="0 0 0" xyz="0 0 0"/>
      </geometry>
      <material name="black" />
    </visual>
    <collision>
      <geometry>
        <box size="0.2 0.1 0.05"/>
        <origin rpy="0 0 0" xyz="0 0 0"/>
      </geometry>
    </collision>
    <inertial>
      <mass value="1"/>
      <inertia ixx="0.1" ixy="0" ixz="0" iyy="0.1" iyz="0" izz="0.1"/>
    </inertial>
  </link>

  <joint name="joint_link10_link12" type="fixed">
    <origin rpy="0 0 -0.75" xyz="-0.05 0.06 0"/>
    <parent link="link10"/>
    <child link="link12"/>
    <axis xyz="0 0 1"/>
    <limit effort="100" velocity="1" lower="-0.065" upper="0.565"/>
  </joint>

  <link name="link13">
    <visual>
      <geometry>
        <cylinder length="0.075" radius="0.065"/>
        <origin rpy="0 0 0" xyz="0 0 0"/>
      </geometry>
      <material name="grey" />
    </visual>
    <collision>
      <geometry>
        <cylinder length="0.075" radius="0.065"/>
        <origin rpy="0 0 0" xyz="0 0 0"/>
      </geometry>
    </collision>
    <inertial>
      <mass value="1"/>
      <inertia ixx="0.1" ixy="0" ixz="0" iyy="0.1" iyz="0" izz="0.1"/>
    </inertial>
  </link>

  <joint name="joint_link11_link13" type="revolute">
    <origin rpy="0 0 0" xyz="-0.1 -0.015 0"/>
    <parent link="link11"/>
    <child link="link13"/>
    <axis xyz="0 0 1"/>
    <limit effort="100" velocity="1" lower="-0.465" upper="0.165"/>
  </joint>

  <link name="link14">
    <visual>
      <geometry>
        <cylinder length="0.075" radius="0.065"/>
        <origin rpy="0 0 0" xyz="0 0 0"/>
      </geometry>
      <material name="grey" />
    </visual>
    <collision>
      <geometry>
        <cylinder length="0.075" radius="0.065"/>
        <origin rpy="0 0 0" xyz="0 0 0"/>
      </geometry>
    </collision>
    <inertial>
      <mass value="1"/>
      <inertia ixx="0.1" ixy="0" ixz="0" iyy="0.1" iyz="0" izz="0.1"/>
    </inertial>
  </link>

  <joint name="joint_link12_link14" type="revolute">
    <origin rpy="0 0 0" xyz="-0.1 -0.015 0"/>
    <parent link="link12"/>
    <child link="link14"/>
    <axis xyz="0 0 1"/>
    <limit effort="100" velocity="1" lower="-0.465" upper="0.165"/>
  </joint>

  <link name="link15">
    <visual>
      <geometry>
        <box size="0.1 0.25 0.08"/>
        <origin rpy="0 0 0" xyz="0 0 0"/>
      </geometry>
      <material name="black" />
    </visual>
    <collision>
      <geometry>
        <box size="0.1 0.25 0.08"/>
        <origin rpy="0 0 0" xyz="0 0 0"/>
      </geometry>
    </collision>
    <inertial>
      <mass value="1"/>
      <inertia ixx="0.1" ixy="0" ixz="0" iyy="0.1" iyz="0" izz="0.1"/>
    </inertial>
  </link>

  <joint name="joint_link13_link15" type="fixed">
    <origin rpy="0 0 -0.42" xyz="-0.05 -0.03 -0.01"/>
    <parent link="link13"/>
    <child link="link15"/>
    <axis xyz="0 0 1"/>
    <limit effort="100" velocity="1" lower="-0.465" upper="0.165"/>
  </joint>

  <link name="link16">
    <visual>
      <geometry>
        <box size="0.1 0.25 0.08"/>
        <origin rpy="0 0 0" xyz="0 0 0"/>
      </geometry>
      <material name="black" />
    </visual>
    <collision>
      <geometry>
        <box size="0.1 0.25 0.08"/>
        <origin rpy="0 0 0" xyz="0 0 0"/>
      </geometry>
    </collision>
    <inertial>
      <mass value="1"/>
      <inertia ixx="0.1" ixy="0" ixz="0" iyy="0.1" iyz="0" izz="0.1"/>
    </inertial>
  </link>

  <joint name="joint_link14_link16" type="fixed">
    <origin rpy="0 0 -0.42" xyz="-0.05 -0.03 0.01"/>
    <parent link="link14"/>
    <child link="link16"/>
    <axis xyz="0 0 1"/>
    <limit effort="100" velocity="1" lower="-0.465" upper="0.165"/>
  </joint>
</robot>
